Workbook
Name CF: Funções!$L$12:$L$1000
Name Data: Contagem!$Z$11
Name Projeto: Contagem!$F$9
Name Responsável: Contagem!$F$11
Name Revisão: Contagem!$Z$12
Name Revisor: Contagem!$F$12
Name UFPB: Contagem!$AA$16
Name VAF: #REF!
Name VAFA: #REF!
Name VAFB: #REF!

Sheet Contagem
D1: Sudoeste Informática
D2: Sudoeste Informática e Consultoria
D3: Missão: "Ser a mais completa solução na área de Tecnologia da Informação, de forma a contribuir para a modernização da Gestão pública."
A4: Identificação da Contagem
A7: Empresa | F7: Sudoeste Informática | R7: R$/PF | T7: 700 | W7: Custo | Y7: =Y8*T7
A8: Aplicação | F8: Viabiliza — Sistema de Licenciamento Eletrônico da SEDUR | W8: PF | Y8: =SUM(AA15:AA18)
A9: Projeto | F9: Recontagem IFPUG - Projeto de Desenvolvimento (aplicação completa)
A10: DV Número | F10: DV-SILE-003 | K10: Versão | N10: 4.0
A11: Responsável | F11: Equipe de Análise — Sudoeste Informática | W11: Criação | Z11: 46311
A12: Revisor | W12: Revisão
A14: Tipo de contagem | C14: Estimativa | O14: Sumário | Q14: PF não Ajustado | W14: Deflator | AA14: PF Local
C15: Projeto de Desenvolvimento | L15: x | Q15: ADD | S15: =Sumário!E57 | W15: 1 | AA15: =S15*W15
C16: Projeto de Melhoria | Q16: CHG | S16: =Sumário!E58 | W16: 0.8 | AA16: =S16*W16
C17: Aplicação ( Baseline ) | Q17: DEL | S17: =Sumário!E59 | W17: 0.3 | AA17: =S17*W17
Q18: TST | S18: =Sumário!E60 | W18: 0.5 | AA18: =S18*W18
K20: Propósito da Contagem
A21: Recontagem integral do tamanho funcional do Viabiliza em 16/10/2026, como projeto de desenvolvimento, seguindo o Manual de Práticas de Contagem IFPUG CPM 4.3.1. A contagem foi refeita a partir do código-fonte atual (rotas, telas, serviços, models, migrations, comandos agendados e testes), sem presumir que as funções da contagem de 01/10/2026 (versão 3.3, 1.618 PF não ajustados) continuassem válidas: cada função anterior foi conferida no código e classificada como mantida, alterada ou removida, e as funções novas foram identificadas. A coluna Observações traz, para cada função, a prova no código, a justificativa de processo elementar ou de arquivo lógico, a classificação, a lista dos DER que formam o TD e dos arquivos que formam o AR/TR, e a situação em relação à contagem anterior. Resultado: 1713 PF não ajustados. As funções removidas, as correções e as premissas estão na memória de cálculo entregue com esta planilha.
K44: Escopo da Contagem
A45: Fronteira: aplicação Viabiliza (Sistema de Licenciamento Eletrônico da SEDUR) completa, no estado do código em 16/10/2026. Inclui o console de gestão da SEDUR, o Portal do Cidadão (conta, empresas, procurações, solicitação, renovação e acompanhamento), a consulta prévia de viabilidade, a consulta pública de protocolo, a verificação pública de documentos, o recebimento de declarações do REGIN/JUCEB, as rotinas automáticas de prazos e controle, a importação mensal do benchmark REDESIM e os dados externos efetivamente lidos (GeoServer da SEDUR, contatos cadastrais da SEDUR, cadastro imobiliário da SEFAZ, lotes do SEMAP, diretório da SEDUR e geocodificação). Fora da contagem: login gov.br (implementado, mas desligado e sem credencial), envio à SEFAZ (bloqueado, HU-110), migração do legado, dados de código (CPM Parte 1 §5.4.2 d e Parte 3 Cap. 1: tipo de serviço, zona urbanística e via) e as transações que só os mantêm, funções técnicas sem efeito para o usuário (teste de conexão, ping, metadados, documentação OpenAPI, retenção de dados, reprocessamento técnico, comandos de suporte) e efeitos automáticos de outra função (envio do parecer à JUCEB, notificações e e-mails). Critério de conferência: linhas F1, F2 etc. são grupos funcionais e não pontuam. Cada função contável tem tipo, TD, AR/TR e Observações com a prova e a lista de DER e de arquivos. Todo arquivo citado no AR é ALI ou AIE desta contagem; subgrupos aparecem pelo arquivo pai. Registros automáticos em arquivos de log (trilha de auditoria, registro de acesso, chamada de integração, envio de e-mail, notificação e comunicação) contam como arquivo referenciado quando gravados no mesmo processamento (CPM Parte 1 §5.5.3 e §5.5.4).

Sheet Funções
B4: Planilha de contagem de ponto de função
B7: =Contagem!A8&" : "&Contagem!F8 | H7: =Contagem!A9&" : "&Contagem!F9
B8: DV Número: | F8: Versão: | G8: =Contagem!N10 | H8: Tipo da Contagem: | K8: =IF(ISBLANK(Contagem!L14),IF(ISBLANK(Contagem!L15),IF(ISBLANK(Contagem!L16),IF(ISBLANK(Contagem!L17),"","Aplicação (Baseline)"),"Melhoria"),"Desenvolvimento"),"Estimativa")
B9: =Contagem!A11&" : "&Contagem!F11 | H9: =Contagem!A12&" : "&Contagem!F12
B10: =Contagem!A7&" : "&Contagem!F7 | O10: ="PF = "&VALUE(Contagem!Y8)
B11: Id. Func | C11: Função Transacional (EE, CE, SE) ou Função de Dados (ALI, AIE) | H11: Tipo | I11: (I/A/E/T) | J11: TD | K11: AR/TR | L11: ctl | M11: C | N11: Complex. | O11: PF | P11: PF Local | Q11: Observações
A12: =IF(D12="",IF(C12="","",1),"") | B12: =CONCATENATE("F",A12) | C12: CNAEs | L12: =CONCATENATE(H12,M12) | M12: =IF(OR(ISBLANK(J12),ISBLANK(K12)),IF(OR(H12="ALI",H12="AIE"),"L",IF(ISBLANK(H12),"","A")),IF(H12="EE",IF(K12>=3,IF(J12>=5,"H","A"),IF(K12>=2,IF(J12>=16,"H",IF(J12<=4,"L","A")),IF(J12<=15,"L","A"))),IF(OR(H12="SE",H12="CE"),IF(K12>=4,IF(J12>=6,"H","A"),IF(K12>=2,IF(J12>=20,"H",IF(J12<=5,"L","A")),IF(J12<=19,"L","A"))),IF(OR(H12="ALI",H12="AIE"),IF(K12>=6,IF(J12>=20,"H","A"),IF(K12>=2,IF(J12>=51,"H",IF(J12<=19,"L","A")),IF(J12<=50,"L","A"))))))) | N12: =IF(M12="L","Baixa",IF(M12="A","Média",IF(M12="","","Alta"))) | O12: =IF(ISBLANK(H12),"",IF(H12="ALI",IF(M12="L",7,IF(M12="A",10,15)),IF(H12="AIE",IF(M12="L",5,IF(M12="A",7,10)),IF(H12="SE",IF(M12="L",4,IF(M12="A",5,7)),IF(OR(H12="EE",H12="CE"),IF(M12="L",3,IF(M12="A",4,6))))))) | P12: =IF(I12="I",O12*Contagem!$W$15,IF(I12="E",O12*Contagem!$W$17,IF(I12="A",O12*Contagem!$W$16,IF(I12="T",O12*Contagem!$W$18,""))))
A13: =IF(H13="",IF(C13="",A12,A12+1),A12) | B13: =IF(A13=A12,"",CONCATENATE("F",A13)) | C13: Dados - CNAE | H13: ALI | I13: I | J13: 15 | K13: 1 | L13: =CONCATENATE(H13,M13) | M13: =IF(OR(ISBLANK(J13),ISBLANK(K13)),IF(OR(H13="ALI",H13="AIE"),"L",IF(ISBLANK(H13),"","A")),IF(H13="EE",IF(K13>=3,IF(J13>=5,"H","A"),IF(K13>=2,IF(J13>=16,"H",IF(J13<=4,"L","A")),IF(J13<=15,"L","A"))),IF(OR(H13="SE",H13="CE"),IF(K13>=4,IF(J13>=6,"H","A"),IF(K13>=2,IF(J13>=20,"H",IF(J13<=5,"L","A")),IF(J13<=19,"L","A"))),IF(OR(H13="ALI",H13="AIE"),IF(K13>=6,IF(J13>=20,"H","A"),IF(K13>=2,IF(J13>=51,"H",IF(J13<=19,"L","A")),IF(J13<=50,"L","A"))))))) | N13: =IF(M13="L","Baixa",IF(M13="A","Média",IF(M13="","","Alta"))) | O13: =IF(ISBLANK(H13),"",IF(H13="ALI",IF(M13="L",7,IF(M13="A",10,15)),IF(H13="AIE",IF(M13="L",5,IF(M13="A",7,10)),IF(H13="SE",IF(M13="L",4,IF(M13="A",5,7)),IF(OR(H13="EE",H13="CE"),IF(M13="L",3,IF(M13="A",4,6))))))) | P13: =IF(I13="I",O13*Contagem!$W$15,IF(I13="E",O13*Contagem!$W$17,IF(I13="A",O13*Contagem!$W$16,IF(I13="T",O13*Contagem!$W$18,"")))) | Q13: Prova: Model app/Models/Cnae.php; migrations database/migrations/2026_06_10_144536_create_cnaes_table.php e 2026_08_13_120000_add_regras_risco_to_cnaes_table.php. Mantido pelos processos CNAEs - incluir, alterar, alterar situação e excluir (CnaeController), auditados via HasAuditoria. Teste: tests/Feature/Cnae/CnaeCrudTest.php::test_mudancas_sao_auditadas_com_attribute_changes. Arquivo lógico: Grupo lógico reconhecido pelo gestor: catálogo de atividades econômicas (CNAE IBGE) com hierarquia e regras de RT e multiplicador usadas na viabilidade; mantido por tela própria. TD=15 (código, denominação, código da seção, descrição da seção, código da divisão, descrição da divisão, código do grupo, descrição do grupo, código da classe, descrição da classe, situação, exige RT, exige RT se alto risco, exige fator multiplicador, exige detalhamento do multiplicador). TR=1 (CNAE). Recontagem 16/10/2026: mantida (linha 168 da contagem de 01/10/2026).
A14: =IF(H14="",IF(C14="",A13,A13+1),A13) | B14: =IF(A14=A13,"",CONCATENATE("F",A14)) | C14: Dados - Classificação de risco municipal | H14: ALI | I14: I | J14: 5 | K14: 1 | L14: =CONCATENATE(H14,M14) | M14: =IF(OR(ISBLANK(J14),ISBLANK(K14)),IF(OR(H14="ALI",H14="AIE"),"L",IF(ISBLANK(H14),"","A")),IF(H14="EE",IF(K14>=3,IF(J14>=5,"H","A"),IF(K14>=2,IF(J14>=16,"H",IF(J14<=4,"L","A")),IF(J14<=15,"L","A"))),IF(OR(H14="SE",H14="CE"),IF(K14>=4,IF(J14>=6,"H","A"),IF(K14>=2,IF(J14>=20,"H",IF(J14<=5,"L","A")),IF(J14<=19,"L","A"))),IF(OR(H14="ALI",H14="AIE"),IF(K14>=6,IF(J14>=20,"H","A"),IF(K14>=2,IF(J14>=51,"H",IF(J14<=19,"L","A")),IF(J14<=50,"L","A"))))))) | N14: =IF(M14="L","Baixa",IF(M14="A","Média",IF(M14="","","Alta"))) | O14: =IF(ISBLANK(H14),"",IF(H14="ALI",IF(M14="L",7,IF(M14="A",10,15)),IF(H14="AIE",IF(M14="L",5,IF(M14="A",7,10)),IF(H14="SE",IF(M14="L",4,IF(M14="A",5,7)),IF(OR(H14="EE",H14="CE"),IF(M14="L",3,IF(M14="A",4,6))))))) | P14: =IF(I14="I",O14*Contagem!$W$15,IF(I14="E",O14*Contagem!$W$17,IF(I14="A",O14*Contagem!$W$16,IF(I14="T",O14*Contagem!$W$18,"")))) | Q14: Prova: Model RiskClassification (HasAuditoria); migration 2026_06_14_014716_create_risk_classifications_table (chave versão de regras + CNAE). Mantida pelo gestor no cadastro de CNAEs: CnaeController@store e update gravam o grau de risco municipal da versão vigente (updateOrCreate), transações contadas na área de CNAEs (CNAEs - incluir e CNAEs - alterar, que já citam este arquivo como FTR). A carga oficial RiscoMunicipalImportService só roda pelo RiscoMunicipalSeeder (carga técnica). O comando risco:classificar (RiscoClassificarCommand) só lê e imprime a classificação no console para conferência técnica: não mantém o arquivo nem é função do usuário. Lida pelo motor de risco (RiscoClassificationService) e pelas consultas de viabilidade. Arquivo lógico: tabela legal versionada (Decreto 32.636/2020) reconhecida pelo gestor; o grau de risco decide o fluxo e não é substituível por descrição, logo não é dado de código. Teste: tests/Feature/Cnae/CnaeCrudTest.php::test_criar_cnae_grava_classificacao_de_risco_municipal_direto. TD=5 (CNAE, risco municipal, condicionantes, observação, versão de regras). TR=1 (Classificação de risco municipal). Recontagem 16/10/2026: mantida (linha 497 da contagem de 01/10/2026).
A15: =IF(H15="",IF(C15="",A14,A14+1),A14) | B15: =IF(A15=A14,"",CONCATENATE("F",A15)) | C15: CNAEs - consultar | H15: CE | I15: I | J15: 6 | K15: 1 | L15: =CONCATENATE(H15,M15) | M15: =IF(OR(ISBLANK(J15),ISBLANK(K15)),IF(OR(H15="ALI",H15="AIE"),"L",IF(ISBLANK(H15),"","A")),IF(H15="EE",IF(K15>=3,IF(J15>=5,"H","A"),IF(K15>=2,IF(J15>=16,"H",IF(J15<=4,"L","A")),IF(J15<=15,"L","A"))),IF(OR(H15="SE",H15="CE"),IF(K15>=4,IF(J15>=6,"H","A"),IF(K15>=2,IF(J15>=20,"H",IF(J15<=5,"L","A")),IF(J15<=19,"L","A"))),IF(OR(H15="ALI",H15="AIE"),IF(K15>=6,IF(J15>=20,"H","A"),IF(K15>=2,IF(J15>=51,"H",IF(J15<=19,"L","A")),IF(J15<=50,"L","A"))))))) | N15: =IF(M15="L","Baixa",IF(M15="A","Média",IF(M15="","","Alta"))) | O15: =IF(ISBLANK(H15),"",IF(H15="ALI",IF(M15="L",7,IF(M15="A",10,15)),IF(H15="AIE",IF(M15="L",5,IF(M15="A",7,10)),IF(H15="SE",IF(M15="L",4,IF(M15="A",5,7)),IF(OR(H15="EE",H15="CE"),IF(M15="L",3,IF(M15="A",4,6))))))) | P15: =IF(I15="I",O15*Contagem!$W$15,IF(I15="E",O15*Contagem!$W$17,IF(I15="A",O15*Contagem!$W$16,IF(I15="T",O15*Contagem!$W$18,"")))) | Q15: Prova: Rota GET /gestao/cnaes (permissão consultar-cnaes). Tela: gestao/cnaes/index. O gestor pesquisa por código (prefixo de dígitos) ou denominação, filtra por situação e ordena. Lê CNAE; não grava. A exportação (?formato=csv/xlsx/pdf, ReportExporter) não tem botão nesta tela (a página não usa ExportMenu; só é alcançável digitando a URL) e não é contada como função; a consulta da tela não grava Trilha de auditoria (o log só ocorre no ramo ?formato=), por isso continua sem FTR de registro. Teste: tests/Feature/Cnae/CnaeCrudTest.php::test_busca_filtra_por_codigo_ou_denominacao. Processo elementar independente: menor unidade com significado para o gestor; completa por si (informa filtro e recebe a lista); deixa o negócio consistente (nada é gravado); lógica única (busca por prefixo de dígitos ou denominação). Classificação: recuperação sem cálculo nem dado derivado, CE (§5.5.3). TD=6 (código, denominação, situação, classe, busca por código ou denominação, ação pesquisar). O filtro de situação é o mesmo campo da coluna situação e conta uma vez (DER único); ordenação e paginação não contam. AR=1 (CNAE). Recontagem 16/10/2026: alterada (linha 169 da contagem de 01/10/2026: "CNAEs - consultar", CE Baixa 3 PF, TD 7, AR 1). Motivo: TD 7→6: situação e filtro de situação eram contados como dois DER; são o mesmo campo. PF inalterado (CE Baixa).
A16: =IF(H16="",IF(C16="",A15,A15+1),A15) | B16: =IF(A16=A15,"",CONCATENATE("F",A16)) | C16: CNAEs - incluir | H16: EE | I16: I | J16: 18 | K16: 3 | L16: =CONCATENATE(H16,M16) | M16: =IF(OR(ISBLANK(J16),ISBLANK(K16)),IF(OR(H16="ALI",H16="AIE"),"L",IF(ISBLANK(H16),"","A")),IF(H16="EE",IF(K16>=3,IF(J16>=5,"H","A"),IF(K16>=2,IF(J16>=16,"H",IF(J16<=4,"L","A")),IF(J16<=15,"L","A"))),IF(OR(H16="SE",H16="CE"),IF(K16>=4,IF(J16>=6,"H","A"),IF(K16>=2,IF(J16>=20,"H",IF(J16<=5,"L","A")),IF(J16<=19,"L","A"))),IF(OR(H16="ALI",H16="AIE"),IF(K16>=6,IF(J16>=20,"H","A"),IF(K16>=2,IF(J16>=51,"H",IF(J16<=19,"L","A")),IF(J16<=50,"L","A"))))))) | N16: =IF(M16="L","Baixa",IF(M16="A","Média",IF(M16="","","Alta"))) | O16: =IF(ISBLANK(H16),"",IF(H16="ALI",IF(M16="L",7,IF(M16="A",10,15)),IF(H16="AIE",IF(M16="L",5,IF(M16="A",7,10)),IF(H16="SE",IF(M16="L",4,IF(M16="A",5,7)),IF(OR(H16="EE",H16="CE"),IF(M16="L",3,IF(M16="A",4,6))))))) | P16: =IF(I16="I",O16*Contagem!$W$15,IF(I16="E",O16*Contagem!$W$17,IF(I16="A",O16*Contagem!$W$16,IF(I16="T",O16*Contagem!$W$18,"")))) | Q16: Prova: Rota POST /gestao/cnaes (manter-cnaes). Tela: gestao/cnaes/criar. O gestor cadastra o CNAE e o grau de risco municipal. Lê versão vigente (subgrupo do arquivo versionado) vigente de risco municipal; grava CNAE, Classificação de risco municipal e Trilha de auditoria. Resultado: atividade disponível para viabilidade. Teste: tests/Feature/Cnae/CnaeCrudTest.php::test_criar_cnae_grava_classificacao_de_risco_municipal_direto. Processo elementar independente: menor unidade com significado para o gestor; completa por si (preenche a ficha e recebe confirmação); deixa o negócio consistente (CNAE e risco gravados na mesma transação); lógica única (exige versão vigente de risco municipal). TD=18 (código, denominação, código da seção, descrição da seção, código da divisão, descrição da divisão, código do grupo, descrição do grupo, código da classe, descrição da classe, situação, exige RT, exige RT se alto risco, exige fator multiplicador, exige detalhamento do multiplicador, grau de risco municipal, mensagem, ação salvar). AR=3 (CNAE, Classificação de risco municipal, Trilha de auditoria). Registros automáticos contados como FTR (premissa P4): Trilha de auditoria. Recontagem (catálogo): Versão de regras deixou de ser arquivo lógico próprio e é subgrupo de arquivo já listado no AR; AR ajustado. Recontagem 16/10/2026: alterada (linha 170 da contagem de 01/10/2026: "CNAEs - incluir", EE Alta 6 PF, TD 18, AR 4). Motivo: Catálogo: retirado Versão de regras (subgrupo de outro arquivo).
A17: =IF(H17="",IF(C17="",A16,A16+1),A16) | B17: =IF(A17=A16,"",CONCATENATE("F",A17)) | C17: CNAEs - alterar | H17: EE | I17: I | J17: 18 | K17: 4 | L17: =CONCATENATE(H17,M17) | M17: =IF(OR(ISBLANK(J17),ISBLANK(K17)),IF(OR(H17="ALI",H17="AIE"),"L",IF(ISBLANK(H17),"","A")),IF(H17="EE",IF(K17>=3,IF(J17>=5,"H","A"),IF(K17>=2,IF(J17>=16,"H",IF(J17<=4,"L","A")),IF(J17<=15,"L","A"))),IF(OR(H17="SE",H17="CE"),IF(K17>=4,IF(J17>=6,"H","A"),IF(K17>=2,IF(J17>=20,"H",IF(J17<=5,"L","A")),IF(J17<=19,"L","A"))),IF(OR(H17="ALI",H17="AIE"),IF(K17>=6,IF(J17>=20,"H","A"),IF(K17>=2,IF(J17>=51,"H",IF(J17<=19,"L","A")),IF(J17<=50,"L","A"))))))) | N17: =IF(M17="L","Baixa",IF(M17="A","Média",IF(M17="","","Alta"))) | O17: =IF(ISBLANK(H17),"",IF(H17="ALI",IF(M17="L",7,IF(M17="A",10,15)),IF(H17="AIE",IF(M17="L",5,IF(M17="A",7,10)),IF(H17="SE",IF(M17="L",4,IF(M17="A",5,7)),IF(OR(H17="EE",H17="CE"),IF(M17="L",3,IF(M17="A",4,6))))))) | P17: =IF(I17="I",O17*Contagem!$W$15,IF(I17="E",O17*Contagem!$W$17,IF(I17="A",O17*Contagem!$W$16,IF(I17="T",O17*Contagem!$W$18,"")))) | Q17: Prova: Rota PUT /gestao/cnaes/{cnae} (manter-cnaes). Tela: gestao/cnaes/editar. O gestor altera a ficha do CNAE. Lê versão vigente (subgrupo do arquivo versionado); grava CNAE e Classificação de risco municipal; ao mudar o código, atualiza o código em Atividade permitida em escritório virtual e nas tabelas de apoio carregadas por seeder, que não são arquivo lógico e não entram no AR; grava Trilha. Teste: tests/Feature/Cnae/CnaeCrudTest.php::test_edicao_atualiza_codigo_hierarquia_e_dados. Processo elementar independente: menor unidade com significado para o gestor; completa por si (edita e recebe confirmação); deixa o negócio consistente (regras acompanham a troca de código); lógica única (realocação do código nas tabelas de regras). TD=18 (código, denominação, código da seção, descrição da seção, código da divisão, descrição da divisão, código do grupo, descrição do grupo, código da classe, descrição da classe, situação, exige RT, exige RT se alto risco, exige fator multiplicador, exige detalhamento do multiplicador, grau de risco municipal, mensagem, ação salvar). AR=4 (CNAE, Classificação de risco municipal, Atividade permitida em escritório virtual, Trilha de auditoria). Registros automáticos contados como FTR (premissa P4): Trilha de auditoria. Recontagem (catálogo): Versão de regras deixou de ser arquivo lógico próprio e é subgrupo de arquivo já listado no AR; AR ajustado. Recontagem 16/10/2026: alterada (linha 171 da contagem de 01/10/2026: "CNAEs - alterar", EE Alta 6 PF, TD 18, AR 5). Motivo: Catálogo: retirado Versão de regras (subgrupo de outro arquivo).
A18: =IF(H18="",IF(C18="",A17,A17+1),A17) | B18: =IF(A18=A17,"",CONCATENATE("F",A18)) | C18: CNAEs - alterar situação | H18: EE | I18: I | J18: 3 | K18: 2 | L18: =CONCATENATE(H18,M18) | M18: =IF(OR(ISBLANK(J18),ISBLANK(K18)),IF(OR(H18="ALI",H18="AIE"),"L",IF(ISBLANK(H18),"","A")),IF(H18="EE",IF(K18>=3,IF(J18>=5,"H","A"),IF(K18>=2,IF(J18>=16,"H",IF(J18<=4,"L","A")),IF(J18<=15,"L","A"))),IF(OR(H18="SE",H18="CE"),IF(K18>=4,IF(J18>=6,"H","A"),IF(K18>=2,IF(J18>=20,"H",IF(J18<=5,"L","A")),IF(J18<=19,"L","A"))),IF(OR(H18="ALI",H18="AIE"),IF(K18>=6,IF(J18>=20,"H","A"),IF(K18>=2,IF(J18>=51,"H",IF(J18<=19,"L","A")),IF(J18<=50,"L","A"))))))) | N18: =IF(M18="L","Baixa",IF(M18="A","Média",IF(M18="","","Alta"))) | O18: =IF(ISBLANK(H18),"",IF(H18="ALI",IF(M18="L",7,IF(M18="A",10,15)),IF(H18="AIE",IF(M18="L",5,IF(M18="A",7,10)),IF(H18="SE",IF(M18="L",4,IF(M18="A",5,7)),IF(OR(H18="EE",H18="CE"),IF(M18="L",3,IF(M18="A",4,6))))))) | P18: =IF(I18="I",O18*Contagem!$W$15,IF(I18="E",O18*Contagem!$W$17,IF(I18="A",O18*Contagem!$W$16,IF(I18="T",O18*Contagem!$W$18,"")))) | Q18: Prova: Rota PUT /gestao/cnaes/{cnae}/situacao (manter-cnaes). Tela: gestao/cnaes/index. O gestor ativa ou desativa o CNAE na lista. Grava a situação do CNAE e Trilha de auditoria. Resultado: atividade deixa ou volta a ser aceita. Teste: tests/Feature/Cnae/CnaeCrudTest.php::test_toggle_de_situacao_funciona_com_payload_minimo. Processo elementar independente: menor unidade com significado para o gestor; completa por si (um clique e confirmação); deixa o negócio consistente (só a situação muda); lógica única (payload mínimo sem regras de risco, distinta do alterar). TD=3 (situação, mensagem, ação ativar/desativar). AR=2 (CNAE, Trilha de auditoria). Registros automáticos contados como FTR (premissa P4): Trilha de auditoria. Recontagem 16/10/2026: mantida (linha 172 da contagem de 01/10/2026).
A19: =IF(H19="",IF(C19="",A18,A18+1),A18) | B19: =IF(A19=A18,"",CONCATENATE("F",A19)) | C19: CNAEs - excluir | H19: EE | I19: I | J19: 3 | K19: 3 | L19: =CONCATENATE(H19,M19) | M19: =IF(OR(ISBLANK(J19),ISBLANK(K19)),IF(OR(H19="ALI",H19="AIE"),"L",IF(ISBLANK(H19),"","A")),IF(H19="EE",IF(K19>=3,IF(J19>=5,"H","A"),IF(K19>=2,IF(J19>=16,"H",IF(J19<=4,"L","A")),IF(J19<=15,"L","A"))),IF(OR(H19="SE",H19="CE"),IF(K19>=4,IF(J19>=6,"H","A"),IF(K19>=2,IF(J19>=20,"H",IF(J19<=5,"L","A")),IF(J19<=19,"L","A"))),IF(OR(H19="ALI",H19="AIE"),IF(K19>=6,IF(J19>=20,"H","A"),IF(K19>=2,IF(J19>=51,"H",IF(J19<=19,"L","A")),IF(J19<=50,"L","A"))))))) | N19: =IF(M19="L","Baixa",IF(M19="A","Média",IF(M19="","","Alta"))) | O19: =IF(ISBLANK(H19),"",IF(H19="ALI",IF(M19="L",7,IF(M19="A",10,15)),IF(H19="AIE",IF(M19="L",5,IF(M19="A",7,10)),IF(H19="SE",IF(M19="L",4,IF(M19="A",5,7)),IF(OR(H19="EE",H19="CE"),IF(M19="L",3,IF(M19="A",4,6))))))) | P19: =IF(I19="I",O19*Contagem!$W$15,IF(I19="E",O19*Contagem!$W$17,IF(I19="A",O19*Contagem!$W$16,IF(I19="T",O19*Contagem!$W$18,"")))) | Q19: Prova: Rota DELETE /gestao/cnaes/{cnae} (manter-cnaes). Tela: gestao/cnaes/index. O gestor exclui o CNAE. Lê Empresa (vínculo company_cnae) para bloquear; exclui CNAE e grava Trilha de auditoria. Resultado: CNAE sem uso removido. Teste: tests/Feature/Cnae/CnaeCrudTest.php::test_exclusao_de_cnae_vinculado_a_empresa_e_bloqueada. Processo elementar independente: menor unidade com significado para o gestor; completa por si (confirma e recebe resultado); deixa o negócio consistente (não exclui CNAE em uso); lógica única (bloqueio por vínculo com empresa). TD=3 (CNAE selecionado, mensagem, ação excluir). AR=3 (CNAE, Empresa, Trilha de auditoria). Registros automáticos contados como FTR (premissa P4): Trilha de auditoria. Recontagem 16/10/2026: mantida (linha 173 da contagem de 01/10/2026).
A20: =IF(H20="",IF(C20="",A19,A19+1),A19) | B20: =IF(A20=A19,"",CONCATENATE("F",A20)) | L20: =CONCATENATE(H20,M20) | M20: =IF(OR(ISBLANK(J20),ISBLANK(K20)),IF(OR(H20="ALI",H20="AIE"),"L",IF(ISBLANK(H20),"","A")),IF(H20="EE",IF(K20>=3,IF(J20>=5,"H","A"),IF(K20>=2,IF(J20>=16,"H",IF(J20<=4,"L","A")),IF(J20<=15,"L","A"))),IF(OR(H20="SE",H20="CE"),IF(K20>=4,IF(J20>=6,"H","A"),IF(K20>=2,IF(J20>=20,"H",IF(J20<=5,"L","A")),IF(J20<=19,"L","A"))),IF(OR(H20="ALI",H20="AIE"),IF(K20>=6,IF(J20>=20,"H","A"),IF(K20>=2,IF(J20>=51,"H",IF(J20<=19,"L","A")),IF(J20<=50,"L","A"))))))) | N20: =IF(M20="L","Baixa",IF(M20="A","Média",IF(M20="","","Alta"))) | O20: =IF(ISBLANK(H20),"",IF(H20="ALI",IF(M20="L",7,IF(M20="A",10,15)),IF(H20="AIE",IF(M20="L",5,IF(M20="A",7,10)),IF(H20="SE",IF(M20="L",4,IF(M20="A",5,7)),IF(OR(H20="EE",H20="CE"),IF(M20="L",3,IF(M20="A",4,6))))))) | P20: =IF(I20="I",O20*Contagem!$W$15,IF(I20="E",O20*Contagem!$W$17,IF(I20="A",O20*Contagem!$W$16,IF(I20="T",O20*Contagem!$W$18,""))))
A21: =IF(H21="",IF(C21="",A20,A20+1),A20) | B21: =IF(A21=A20,"",CONCATENATE("F",A21)) | C21: Requisitos documentais | L21: =CONCATENATE(H21,M21) | M21: =IF(OR(ISBLANK(J21),ISBLANK(K21)),IF(OR(H21="ALI",H21="AIE"),"L",IF(ISBLANK(H21),"","A")),IF(H21="EE",IF(K21>=3,IF(J21>=5,"H","A"),IF(K21>=2,IF(J21>=16,"H",IF(J21<=4,"L","A")),IF(J21<=15,"L","A"))),IF(OR(H21="SE",H21="CE"),IF(K21>=4,IF(J21>=6,"H","A"),IF(K21>=2,IF(J21>=20,"H",IF(J21<=5,"L","A")),IF(J21<=19,"L","A"))),IF(OR(H21="ALI",H21="AIE"),IF(K21>=6,IF(J21>=20,"H","A"),IF(K21>=2,IF(J21>=51,"H",IF(J21<=19,"L","A")),IF(J21<=50,"L","A"))))))) | N21: =IF(M21="L","Baixa",IF(M21="A","Média",IF(M21="","","Alta"))) | O21: =IF(ISBLANK(H21),"",IF(H21="ALI",IF(M21="L",7,IF(M21="A",10,15)),IF(H21="AIE",IF(M21="L",5,IF(M21="A",7,10)),IF(H21="SE",IF(M21="L",4,IF(M21="A",5,7)),IF(OR(H21="EE",H21="CE"),IF(M21="L",3,IF(M21="A",4,6))))))) | P21: =IF(I21="I",O21*Contagem!$W$15,IF(I21="E",O21*Contagem!$W$17,IF(I21="A",O21*Contagem!$W$16,IF(I21="T",O21*Contagem!$W$18,""))))
A22: =IF(H22="",IF(C22="",A21,A21+1),A21) | B22: =IF(A22=A21,"",CONCATENATE("F",A22)) | C22: Dados - Requisito documental | H22: ALI | I22: I | J22: 7 | K22: 1 | L22: =CONCATENATE(H22,M22) | M22: =IF(OR(ISBLANK(J22),ISBLANK(K22)),IF(OR(H22="ALI",H22="AIE"),"L",IF(ISBLANK(H22),"","A")),IF(H22="EE",IF(K22>=3,IF(J22>=5,"H","A"),IF(K22>=2,IF(J22>=16,"H",IF(J22<=4,"L","A")),IF(J22<=15,"L","A"))),IF(OR(H22="SE",H22="CE"),IF(K22>=4,IF(J22>=6,"H","A"),IF(K22>=2,IF(J22>=20,"H",IF(J22<=5,"L","A")),IF(J22<=19,"L","A"))),IF(OR(H22="ALI",H22="AIE"),IF(K22>=6,IF(J22>=20,"H","A"),IF(K22>=2,IF(J22>=51,"H",IF(J22<=19,"L","A")),IF(J22<=50,"L","A"))))))) | N22: =IF(M22="L","Baixa",IF(M22="A","Média",IF(M22="","","Alta"))) | O22: =IF(ISBLANK(H22),"",IF(H22="ALI",IF(M22="L",7,IF(M22="A",10,15)),IF(H22="AIE",IF(M22="L",5,IF(M22="A",7,10)),IF(H22="SE",IF(M22="L",4,IF(M22="A",5,7)),IF(OR(H22="EE",H22="CE"),IF(M22="L",3,IF(M22="A",4,6))))))) | P22: =IF(I22="I",O22*Contagem!$W$15,IF(I22="E",O22*Contagem!$W$17,IF(I22="A",O22*Contagem!$W$16,IF(I22="T",O22*Contagem!$W$18,"")))) | Q22: Prova: Model app/Models/DocumentRequirement.php; migrations database/migrations/2026_06_14_104827_create_document_requirements_table.php e 2026_06_14_104828_create_cnae_document_requirement_table.php (vínculo N:N com CNAE, sem atributos próprios). Mantido por DocumentRequirementController (store, update, toggle, syncCnaes). Teste: tests/Feature/Solicitacao/DocumentRequirementCrudTest.php::test_cria_requisito_e_audita. Arquivo lógico: Grupo lógico reconhecido pelo gestor: o catálogo de documentos exigidos na solicitação e a obrigatoriedade por CNAE, mantido por tela e consumido pela validação documental. TD=7 (código, nome, descrição, obrigatório, situação (ativo), instruções de validação, CNAEs vinculados). TR=1 (Requisito documental). Recontagem 16/10/2026: mantida (linha 128 da contagem de 01/10/2026).
A23: =IF(H23="",IF(C23="",A22,A22+1),A22) | B23: =IF(A23=A22,"",CONCATENATE("F",A23)) | C23: Requisitos documentais - consultar | H23: CE | I23: I | J23: 10 | K23: 2 | L23: =CONCATENATE(H23,M23) | M23: =IF(OR(ISBLANK(J23),ISBLANK(K23)),IF(OR(H23="ALI",H23="AIE"),"L",IF(ISBLANK(H23),"","A")),IF(H23="EE",IF(K23>=3,IF(J23>=5,"H","A"),IF(K23>=2,IF(J23>=16,"H",IF(J23<=4,"L","A")),IF(J23<=15,"L","A"))),IF(OR(H23="SE",H23="CE"),IF(K23>=4,IF(J23>=6,"H","A"),IF(K23>=2,IF(J23>=20,"H",IF(J23<=5,"L","A")),IF(J23<=19,"L","A"))),IF(OR(H23="ALI",H23="AIE"),IF(K23>=6,IF(J23>=20,"H","A"),IF(K23>=2,IF(J23>=51,"H",IF(J23<=19,"L","A")),IF(J23<=50,"L","A"))))))) | N23: =IF(M23="L","Baixa",IF(M23="A","Média",IF(M23="","","Alta"))) | O23: =IF(ISBLANK(H23),"",IF(H23="ALI",IF(M23="L",7,IF(M23="A",10,15)),IF(H23="AIE",IF(M23="L",5,IF(M23="A",7,10)),IF(H23="SE",IF(M23="L",4,IF(M23="A",5,7)),IF(OR(H23="EE",H23="CE"),IF(M23="L",3,IF(M23="A",4,6))))))) | P23: =IF(I23="I",O23*Contagem!$W$15,IF(I23="E",O23*Contagem!$W$17,IF(I23="A",O23*Contagem!$W$16,IF(I23="T",O23*Contagem!$W$18,"")))) | Q23: Prova: Rota GET /gestao/requisitos-documentais (permissão manter-requisitos-documentais). Tela: gestao/requisitos-documentais/index. O gestor busca e filtra por situação. Lê Requisito documental e CNAE; não grava. Resultado: lista paginada dos requisitos com CNAEs vinculados. Teste: tests/Feature/Solicitacao/DocumentRequirementCrudTest.php::test_administrador_lista_requisitos. Processo elementar independente: menor unidade com significado para o gestor; completa por si (filtro até a lista exibida); deixa o negócio consistente (nada muda); lógica única (recuperação de requisitos com CNAEs vinculados, sem cálculo). TD=10 (código, nome, descrição, obrigatório, situação, instruções de validação, código do CNAE vinculado, descrição do CNAE vinculado, busca por código/nome, ação de consultar). AR=2 (Requisito documental, CNAE). Recontagem 16/10/2026: mantida (linha 129 da contagem de 01/10/2026).
A24: =IF(H24="",IF(C24="",A23,A23+1),A23) | B24: =IF(A24=A23,"",CONCATENATE("F",A24)) | C24: Requisitos documentais - incluir | H24: EE | I24: I | J24: 7 | K24: 2 | L24: =CONCATENATE(H24,M24) | M24: =IF(OR(ISBLANK(J24),ISBLANK(K24)),IF(OR(H24="ALI",H24="AIE"),"L",IF(ISBLANK(H24),"","A")),IF(H24="EE",IF(K24>=3,IF(J24>=5,"H","A"),IF(K24>=2,IF(J24>=16,"H",IF(J24<=4,"L","A")),IF(J24<=15,"L","A"))),IF(OR(H24="SE",H24="CE"),IF(K24>=4,IF(J24>=6,"H","A"),IF(K24>=2,IF(J24>=20,"H",IF(J24<=5,"L","A")),IF(J24<=19,"L","A"))),IF(OR(H24="ALI",H24="AIE"),IF(K24>=6,IF(J24>=20,"H","A"),IF(K24>=2,IF(J24>=51,"H",IF(J24<=19,"L","A")),IF(J24<=50,"L","A"))))))) | N24: =IF(M24="L","Baixa",IF(M24="A","Média",IF(M24="","","Alta"))) | O24: =IF(ISBLANK(H24),"",IF(H24="ALI",IF(M24="L",7,IF(M24="A",10,15)),IF(H24="AIE",IF(M24="L",5,IF(M24="A",7,10)),IF(H24="SE",IF(M24="L",4,IF(M24="A",5,7)),IF(OR(H24="EE",H24="CE"),IF(M24="L",3,IF(M24="A",4,6))))))) | P24: =IF(I24="I",O24*Contagem!$W$15,IF(I24="E",O24*Contagem!$W$17,IF(I24="A",O24*Contagem!$W$16,IF(I24="T",O24*Contagem!$W$18,"")))) | Q24: Prova: Rota POST /gestao/requisitos-documentais (permissão manter-requisitos-documentais). Tela: gestao/requisitos-documentais/index. O gestor informa o requisito; StoreDocumentRequirementRequest valida código único. Grava Requisito documental (ativo) e Trilha de auditoria (HasAuditoria). Resultado: novo documento passa a poder ser exigido. Teste: tests/Feature/Solicitacao/DocumentRequirementCrudTest.php::test_cria_requisito_e_audita. Processo elementar independente: menor unidade com significado para o gestor; completa por si (formulário até o requisito gravado); deixa o negócio consistente (requisito ativo e auditado); lógica única (inclusão com código único). TD=7 (código, nome, descrição, obrigatório, instruções de validação, mensagem de sucesso/erro, ação de salvar). AR=2 (Requisito documental, Trilha de auditoria). Registros automáticos contados como FTR (premissa P4): Trilha de auditoria. Recontagem 16/10/2026: mantida (linha 130 da contagem de 01/10/2026).
A25: =IF(H25="",IF(C25="",A24,A24+1),A24) | B25: =IF(A25=A24,"",CONCATENATE("F",A25)) | C25: Requisitos documentais - alterar | H25: EE | I25: I | J25: 7 | K25: 2 | L25: =CONCATENATE(H25,M25) | M25: =IF(OR(ISBLANK(J25),ISBLANK(K25)),IF(OR(H25="ALI",H25="AIE"),"L",IF(ISBLANK(H25),"","A")),IF(H25="EE",IF(K25>=3,IF(J25>=5,"H","A"),IF(K25>=2,IF(J25>=16,"H",IF(J25<=4,"L","A")),IF(J25<=15,"L","A"))),IF(OR(H25="SE",H25="CE"),IF(K25>=4,IF(J25>=6,"H","A"),IF(K25>=2,IF(J25>=20,"H",IF(J25<=5,"L","A")),IF(J25<=19,"L","A"))),IF(OR(H25="ALI",H25="AIE"),IF(K25>=6,IF(J25>=20,"H","A"),IF(K25>=2,IF(J25>=51,"H",IF(J25<=19,"L","A")),IF(J25<=50,"L","A"))))))) | N25: =IF(M25="L","Baixa",IF(M25="A","Média",IF(M25="","","Alta"))) | O25: =IF(ISBLANK(H25),"",IF(H25="ALI",IF(M25="L",7,IF(M25="A",10,15)),IF(H25="AIE",IF(M25="L",5,IF(M25="A",7,10)),IF(H25="SE",IF(M25="L",4,IF(M25="A",5,7)),IF(OR(H25="EE",H25="CE"),IF(M25="L",3,IF(M25="A",4,6))))))) | P25: =IF(I25="I",O25*Contagem!$W$15,IF(I25="E",O25*Contagem!$W$17,IF(I25="A",O25*Contagem!$W$16,IF(I25="T",O25*Contagem!$W$18,"")))) | Q25: Prova: Rota PUT /gestao/requisitos-documentais/{requirement} (permissão manter-requisitos-documentais). Tela: gestao/requisitos-documentais/index. O gestor edita nome, descrição, obrigatoriedade e instruções; o código fica imutável. Grava Requisito documental e Trilha de auditoria. Resultado: nova regra documental vale para as próximas solicitações. Teste: tests/Feature/Solicitacao/DocumentRequirementCrudTest.php::test_code_unico_e_imutavel_na_edicao. Processo elementar independente: menor unidade com significado para o gestor; completa por si (edição até a gravação); deixa o negócio consistente (requisito alterado e auditado); lógica única (alteração sem mudar o código). TD=7 (código (identificação, imutável), nome, descrição, obrigatório, instruções de validação, mensagem de sucesso/erro, ação de salvar). AR=2 (Requisito documental, Trilha de auditoria). Registros automáticos contados como FTR (premissa P4): Trilha de auditoria. Recontagem 16/10/2026: mantida (linha 131 da contagem de 01/10/2026).
A26: =IF(H26="",IF(C26="",A25,A25+1),A25) | B26: =IF(A26=A25,"",CONCATENATE("F",A26)) | C26: Requisitos documentais - ativar ou inativar | H26: EE | I26: I | J26: 4 | K26: 2 | L26: =CONCATENATE(H26,M26) | M26: =IF(OR(ISBLANK(J26),ISBLANK(K26)),IF(OR(H26="ALI",H26="AIE"),"L",IF(ISBLANK(H26),"","A")),IF(H26="EE",IF(K26>=3,IF(J26>=5,"H","A"),IF(K26>=2,IF(J26>=16,"H",IF(J26<=4,"L","A")),IF(J26<=15,"L","A"))),IF(OR(H26="SE",H26="CE"),IF(K26>=4,IF(J26>=6,"H","A"),IF(K26>=2,IF(J26>=20,"H",IF(J26<=5,"L","A")),IF(J26<=19,"L","A"))),IF(OR(H26="ALI",H26="AIE"),IF(K26>=6,IF(J26>=20,"H","A"),IF(K26>=2,IF(J26>=51,"H",IF(J26<=19,"L","A")),IF(J26<=50,"L","A"))))))) | N26: =IF(M26="L","Baixa",IF(M26="A","Média",IF(M26="","","Alta"))) | O26: =IF(ISBLANK(H26),"",IF(H26="ALI",IF(M26="L",7,IF(M26="A",10,15)),IF(H26="AIE",IF(M26="L",5,IF(M26="A",7,10)),IF(H26="SE",IF(M26="L",4,IF(M26="A",5,7)),IF(OR(H26="EE",H26="CE"),IF(M26="L",3,IF(M26="A",4,6))))))) | P26: =IF(I26="I",O26*Contagem!$W$15,IF(I26="E",O26*Contagem!$W$17,IF(I26="A",O26*Contagem!$W$16,IF(I26="T",O26*Contagem!$W$18,"")))) | Q26: Prova: Rota PUT /gestao/requisitos-documentais/{requirement}/toggle (permissão manter-requisitos-documentais). Tela: gestao/requisitos-documentais/index. O gestor ativa ou inativa sem excluir. Grava Requisito documental e Trilha de auditoria. Resultado: requisito deixa de ser exigido ou volta a ser. Teste: tests/Feature/Solicitacao/DocumentRequirementCrudTest.php::test_desativar_preserva_o_registro. Processo elementar independente: menor unidade com significado para o gestor; completa por si (clique até a nova situação); deixa o negócio consistente (registro preservado, situação trocada); lógica única (alternância de situação, distinta da edição). TD=4 (código do requisito, situação, mensagem de sucesso, ação de ativar/inativar). AR=2 (Requisito documental, Trilha de auditoria). Registros automáticos contados como FTR (premissa P4): Trilha de auditoria. Recontagem 16/10/2026: mantida (linha 132 da contagem de 01/10/2026).
A27: =IF(H27="",IF(C27="",A26,A26+1),A26) | B27: =IF(A27=A26,"",CONCATENATE("F",A27)) | C27: Requisitos documentais - vincular CNAEs | H27: EE | I27: I | J27: 4 | K27: 3 | L27: =CONCATENATE(H27,M27) | M27: =IF(OR(ISBLANK(J27),ISBLANK(K27)),IF(OR(H27="ALI",H27="AIE"),"L",IF(ISBLANK(H27),"","A")),IF(H27="EE",IF(K27>=3,IF(J27>=5,"H","A"),IF(K27>=2,IF(J27>=16,"H",IF(J27<=4,"L","A")),IF(J27<=15,"L","A"))),IF(OR(H27="SE",H27="CE"),IF(K27>=4,IF(J27>=6,"H","A"),IF(K27>=2,IF(J27>=20,"H",IF(J27<=5,"L","A")),IF(J27<=19,"L","A"))),IF(OR(H27="ALI",H27="AIE"),IF(K27>=6,IF(J27>=20,"H","A"),IF(K27>=2,IF(J27>=51,"H",IF(J27<=19,"L","A")),IF(J27<=50,"L","A"))))))) | N27: =IF(M27="L","Baixa",IF(M27="A","Média",IF(M27="","","Alta"))) | O27: =IF(ISBLANK(H27),"",IF(H27="ALI",IF(M27="L",7,IF(M27="A",10,15)),IF(H27="AIE",IF(M27="L",5,IF(M27="A",7,10)),IF(H27="SE",IF(M27="L",4,IF(M27="A",5,7)),IF(OR(H27="EE",H27="CE"),IF(M27="L",3,IF(M27="A",4,6))))))) | P27: =IF(I27="I",O27*Contagem!$W$15,IF(I27="E",O27*Contagem!$W$17,IF(I27="A",O27*Contagem!$W$16,IF(I27="T",O27*Contagem!$W$18,"")))) | Q27: Prova: Rota PUT /gestao/requisitos-documentais/{requirement}/cnaes (permissão manter-requisitos-documentais). Tela: gestao/requisitos-documentais/index. O gestor marca os CNAEs; só CNAE ativo é aceito. Lê CNAE; grava o vínculo do Requisito documental (sync exato) e Trilha de auditoria com antes/depois. Resultado: muda a obrigatoriedade por atividade. Teste: tests/Feature/Solicitacao/DocumentRequirementCrudTest.php::test_vincula_cnaes_por_sync_exato_e_audita. Processo elementar independente: menor unidade com significado para o gestor; completa por si (seleção até o vínculo gravado); deixa o negócio consistente (conjunto exato de CNAEs auditado); lógica única (sincronização N:N com validação de CNAE ativo). TD=4 (código do requisito, CNAEs marcados, mensagem de sucesso/erro, ação de salvar vínculo). AR=3 (Requisito documental, CNAE, Trilha de auditoria). Registros automáticos contados como FTR (premissa P4): Trilha de auditoria. Recontagem 16/10/2026: mantida (linha 133 da contagem de 01/10/2026).
A28: =IF(H28="",IF(C28="",A27,A27+1),A27) | B28: =IF(A28=A27,"",CONCATENATE("F",A28)) | L28: =CONCATENATE(H28,M28) | M28: =IF(OR(ISBLANK(J28),ISBLANK(K28)),IF(OR(H28="ALI",H28="AIE"),"L",IF(ISBLANK(H28),"","A")),IF(H28="EE",IF(K28>=3,IF(J28>=5,"H","A"),IF(K28>=2,IF(J28>=16,"H",IF(J28<=4,"L","A")),IF(J28<=15,"L","A"))),IF(OR(H28="SE",H28="CE"),IF(K28>=4,IF(J28>=6,"H","A"),IF(K28>=2,IF(J28>=20,"H",IF(J28<=5,"L","A")),IF(J28<=19,"L","A"))),IF(OR(H28="ALI",H28="AIE"),IF(K28>=6,IF(J28>=20,"H","A"),IF(K28>=2,IF(J28>=51,"H",IF(J28<=19,"L","A")),IF(J28<=50,"L","A"))))))) | N28: =IF(M28="L","Baixa",IF(M28="A","Média",IF(M28="","","Alta"))) | O28: =IF(ISBLANK(H28),"",IF(H28="ALI",IF(M28="L",7,IF(M28="A",10,15)),IF(H28="AIE",IF(M28="L",5,IF(M28="A",7,10)),IF(H28="SE",IF(M28="L",4,IF(M28="A",5,7)),IF(OR(H28="EE",H28="CE"),IF(M28="L",3,IF(M28="A",4,6))))))) | P28: =IF(I28="I",O28*Contagem!$W$15,IF(I28="E",O28*Contagem!$W$17,IF(I28="A",O28*Contagem!$W$16,IF(I28="T",O28*Contagem!$W$18,""))))
A29: =IF(H29="",IF(C29="",A28,A28+1),A28) | B29: =IF(A29=A28,"",CONCATENATE("F",A29)) | C29: Setores | L29: =CONCATENATE(H29,M29) | M29: =IF(OR(ISBLANK(J29),ISBLANK(K29)),IF(OR(H29="ALI",H29="AIE"),"L",IF(ISBLANK(H29),"","A")),IF(H29="EE",IF(K29>=3,IF(J29>=5,"H","A"),IF(K29>=2,IF(J29>=16,"H",IF(J29<=4,"L","A")),IF(J29<=15,"L","A"))),IF(OR(H29="SE",H29="CE"),IF(K29>=4,IF(J29>=6,"H","A"),IF(K29>=2,IF(J29>=20,"H",IF(J29<=5,"L","A")),IF(J29<=19,"L","A"))),IF(OR(H29="ALI",H29="AIE"),IF(K29>=6,IF(J29>=20,"H","A"),IF(K29>=2,IF(J29>=51,"H",IF(J29<=19,"L","A")),IF(J29<=50,"L","A"))))))) | N29: =IF(M29="L","Baixa",IF(M29="A","Média",IF(M29="","","Alta"))) | O29: =IF(ISBLANK(H29),"",IF(H29="ALI",IF(M29="L",7,IF(M29="A",10,15)),IF(H29="AIE",IF(M29="L",5,IF(M29="A",7,10)),IF(H29="SE",IF(M29="L",4,IF(M29="A",5,7)),IF(OR(H29="EE",H29="CE"),IF(M29="L",3,IF(M29="A",4,6))))))) | P29: =IF(I29="I",O29*Contagem!$W$15,IF(I29="E",O29*Contagem!$W$17,IF(I29="A",O29*Contagem!$W$16,IF(I29="T",O29*Contagem!$W$18,""))))
A30: =IF(H30="",IF(C30="",A29,A29+1),A29) | B30: =IF(A30=A29,"",CONCATENATE("F",A30)) | C30: Dados - Setor | H30: ALI | I30: I | J30: 4 | K30: 1 | L30: =CONCATENATE(H30,M30) | M30: =IF(OR(ISBLANK(J30),ISBLANK(K30)),IF(OR(H30="ALI",H30="AIE"),"L",IF(ISBLANK(H30),"","A")),IF(H30="EE",IF(K30>=3,IF(J30>=5,"H","A"),IF(K30>=2,IF(J30>=16,"H",IF(J30<=4,"L","A")),IF(J30<=15,"L","A"))),IF(OR(H30="SE",H30="CE"),IF(K30>=4,IF(J30>=6,"H","A"),IF(K30>=2,IF(J30>=20,"H",IF(J30<=5,"L","A")),IF(J30<=19,"L","A"))),IF(OR(H30="ALI",H30="AIE"),IF(K30>=6,IF(J30>=20,"H","A"),IF(K30>=2,IF(J30>=51,"H",IF(J30<=19,"L","A")),IF(J30<=50,"L","A"))))))) | N30: =IF(M30="L","Baixa",IF(M30="A","Média",IF(M30="","","Alta"))) | O30: =IF(ISBLANK(H30),"",IF(H30="ALI",IF(M30="L",7,IF(M30="A",10,15)),IF(H30="AIE",IF(M30="L",5,IF(M30="A",7,10)),IF(H30="SE",IF(M30="L",4,IF(M30="A",5,7)),IF(OR(H30="EE",H30="CE"),IF(M30="L",3,IF(M30="A",4,6))))))) | P30: =IF(I30="I",O30*Contagem!$W$15,IF(I30="E",O30*Contagem!$W$17,IF(I30="A",O30*Contagem!$W$16,IF(I30="T",O30*Contagem!$W$18,"")))) | Q30: Prova: Model app/Models/Sector.php; migrations database/migrations/2026_06_14_215040_create_sectors_table.php, 2026_06_14_215041_create_sector_user_table.php e 2026_09_24_222200_add_sector_code_and_user_sector_assignments.php (coluna code = CEIN_NUMERO institucional). Mantido por Setores - incluir, alterar, ativar ou inativar e vincular analistas (SectorController) e pela sincronização da lotação no login AD (UserSectorAssignmentSync). Teste: tests/Feature/Analise/SectorCrudTest.php::test_vincula_e_desvincula_analistas_auditado. Arquivo lógico: o setor é a caixa de análise da distribuição, com analistas vinculados (N:N) e processos distribuídos a ele; a situação decide se recebe novas distribuições. Não é dado de código (Parte 1 §5.4.2 d; Parte 3 Cap. 1): além de código e nome, mantém relacionamento de negócio com analistas e processos, que não se substitui pela descrição. O vínculo sector_user só tem chaves e entra como DER (analista vinculado), não como TR. TD=4 (código institucional (CEIN), nome, situação, analista vinculado). TR=1 (Setor). Recontagem 16/10/2026: alterada (linha 176 da contagem de 01/10/2026: "Dados - Setor", ALI Baixa 7 PF, TD 3, AR 1). Motivo: TD 3→4: migration 2026_09_24_222200 incluiu o código institucional do setor (CEIN), usado para casar a lotação vinda do AD. PF inalterado (ALI Baixa).
A31: =IF(H31="",IF(C31="",A30,A30+1),A30) | B31: =IF(A31=A30,"",CONCATENATE("F",A31)) | C31: Setores - consultar | H31: SE | I31: I | J31: 7 | K31: 3 | L31: =CONCATENATE(H31,M31) | M31: =IF(OR(ISBLANK(J31),ISBLANK(K31)),IF(OR(H31="ALI",H31="AIE"),"L",IF(ISBLANK(H31),"","A")),IF(H31="EE",IF(K31>=3,IF(J31>=5,"H","A"),IF(K31>=2,IF(J31>=16,"H",IF(J31<=4,"L","A")),IF(J31<=15,"L","A"))),IF(OR(H31="SE",H31="CE"),IF(K31>=4,IF(J31>=6,"H","A"),IF(K31>=2,IF(J31>=20,"H",IF(J31<=5,"L","A")),IF(J31<=19,"L","A"))),IF(OR(H31="ALI",H31="AIE"),IF(K31>=6,IF(J31>=20,"H","A"),IF(K31>=2,IF(J31>=51,"H",IF(J31<=19,"L","A")),IF(J31<=50,"L","A"))))))) | N31: =IF(M31="L","Baixa",IF(M31="A","Média",IF(M31="","","Alta"))) | O31: =IF(ISBLANK(H31),"",IF(H31="ALI",IF(M31="L",7,IF(M31="A",10,15)),IF(H31="AIE",IF(M31="L",5,IF(M31="A",7,10)),IF(H31="SE",IF(M31="L",4,IF(M31="A",5,7)),IF(OR(H31="EE",H31="CE"),IF(M31="L",3,IF(M31="A",4,6))))))) | P31: =IF(I31="I",O31*Contagem!$W$15,IF(I31="E",O31*Contagem!$W$17,IF(I31="A",O31*Contagem!$W$16,IF(I31="T",O31*Contagem!$W$18,"")))) | Q31: Prova: Rota GET /gestao/setores (permissão manter-setores). Tela: gestao/setores/index. O gestor lista setores com busca por nome e filtro de situação. Lê Setor, Usuário (analistas) e Solicitação de viabilidade (contagem de processos); não grava. Teste: tests/Feature/Analise/SectorCrudTest.php::test_administrador_lista_setores. Processo elementar independente: menor unidade com significado para o gestor; completa por si (filtra e recebe a lista); deixa o negócio consistente (nada é alterado); lógica única (setores com contagem de analistas e processos). Classificação: exibe contagens calculadas por setor (withCount de analistas e processos), dado derivado: SE, não CE (§5.5.3). TD=7 (busca por nome, situação, nome, quantidade de analistas, quantidade de processos, analistas vinculados, ação de consultar). O filtro de situação é o mesmo campo da coluna situação e conta uma vez (DER único); ordenação e paginação não contam. AR=3 (Setor, Usuário, Solicitação de viabilidade). Recontagem 16/10/2026: alterada (linha 177 da contagem de 01/10/2026: "Setores - consultar", SE Média 5 PF, TD 9, AR 3). Motivo: TD 9→7: ordenação e filtro de situação duplicado não contam; a lista de analistas disponíveis é apoio do formulário de vínculo. PF inalterado (SE Média).
A32: =IF(H32="",IF(C32="",A31,A31+1),A31) | B32: =IF(A32=A31,"",CONCATENATE("F",A32)) | C32: Setores - incluir | H32: EE | I32: I | J32: 4 | K32: 2 | L32: =CONCATENATE(H32,M32) | M32: =IF(OR(ISBLANK(J32),ISBLANK(K32)),IF(OR(H32="ALI",H32="AIE"),"L",IF(ISBLANK(H32),"","A")),IF(H32="EE",IF(K32>=3,IF(J32>=5,"H","A"),IF(K32>=2,IF(J32>=16,"H",IF(J32<=4,"L","A")),IF(J32<=15,"L","A"))),IF(OR(H32="SE",H32="CE"),IF(K32>=4,IF(J32>=6,"H","A"),IF(K32>=2,IF(J32>=20,"H",IF(J32<=5,"L","A")),IF(J32<=19,"L","A"))),IF(OR(H32="ALI",H32="AIE"),IF(K32>=6,IF(J32>=20,"H","A"),IF(K32>=2,IF(J32>=51,"H",IF(J32<=19,"L","A")),IF(J32<=50,"L","A"))))))) | N32: =IF(M32="L","Baixa",IF(M32="A","Média",IF(M32="","","Alta"))) | O32: =IF(ISBLANK(H32),"",IF(H32="ALI",IF(M32="L",7,IF(M32="A",10,15)),IF(H32="AIE",IF(M32="L",5,IF(M32="A",7,10)),IF(H32="SE",IF(M32="L",4,IF(M32="A",5,7)),IF(OR(H32="EE",H32="CE"),IF(M32="L",3,IF(M32="A",4,6))))))) | P32: =IF(I32="I",O32*Contagem!$W$15,IF(I32="E",O32*Contagem!$W$17,IF(I32="A",O32*Contagem!$W$16,IF(I32="T",O32*Contagem!$W$18,"")))) | Q32: Prova: Rota POST /gestao/setores (permissão manter-setores). Tela: gestao/setores/index. O gestor cadastra o setor (SectorRequest, nome único). Grava Setor e Trilha de auditoria (AuditService, ação criar). Resultado: nova caixa de análise disponível. Teste: tests/Feature/Analise/SectorCrudTest.php::test_cria_setor_auditado. Processo elementar independente: menor unidade com significado para o gestor; completa por si (informa nome e situação e recebe a confirmação); deixa o negócio consistente (setor único gravado e auditado); lógica única (inclusão com unicidade de nome). Classificação: mantém ALI, EE. TD=4 (nome, situação, mensagem, ação salvar). AR=2 (Setor, Trilha de auditoria). Registros automáticos contados como FTR (premissa P4): Trilha de auditoria. Recontagem 16/10/2026: alterada (linha 178 da contagem de 01/10/2026: "Setores - incluir", EE Baixa 3 PF, TD 4, AR 1). Motivo: AR 1→2: o controller grava a Trilha de auditoria explicitamente (AuditService). PF inalterado (EE Baixa).
A33: =IF(H33="",IF(C33="",A32,A32+1),A32) | B33: =IF(A33=A32,"",CONCATENATE("F",A33)) | C33: Setores - alterar | H33: EE | I33: I | J33: 4 | K33: 2 | L33: =CONCATENATE(H33,M33) | M33: =IF(OR(ISBLANK(J33),ISBLANK(K33)),IF(OR(H33="ALI",H33="AIE"),"L",IF(ISBLANK(H33),"","A")),IF(H33="EE",IF(K33>=3,IF(J33>=5,"H","A"),IF(K33>=2,IF(J33>=16,"H",IF(J33<=4,"L","A")),IF(J33<=15,"L","A"))),IF(OR(H33="SE",H33="CE"),IF(K33>=4,IF(J33>=6,"H","A"),IF(K33>=2,IF(J33>=20,"H",IF(J33<=5,"L","A")),IF(J33<=19,"L","A"))),IF(OR(H33="ALI",H33="AIE"),IF(K33>=6,IF(J33>=20,"H","A"),IF(K33>=2,IF(J33>=51,"H",IF(J33<=19,"L","A")),IF(J33<=50,"L","A"))))))) | N33: =IF(M33="L","Baixa",IF(M33="A","Média",IF(M33="","","Alta"))) | O33: =IF(ISBLANK(H33),"",IF(H33="ALI",IF(M33="L",7,IF(M33="A",10,15)),IF(H33="AIE",IF(M33="L",5,IF(M33="A",7,10)),IF(H33="SE",IF(M33="L",4,IF(M33="A",5,7)),IF(OR(H33="EE",H33="CE"),IF(M33="L",3,IF(M33="A",4,6))))))) | P33: =IF(I33="I",O33*Contagem!$W$15,IF(I33="E",O33*Contagem!$W$17,IF(I33="A",O33*Contagem!$W$16,IF(I33="T",O33*Contagem!$W$18,"")))) | Q33: Prova: Rota PUT /gestao/setores/{sector} (permissão manter-setores). Tela: gestao/setores/index. O gestor edita nome e situação. Grava Setor e Trilha de auditoria (AuditService, ação atualizar). Teste: tests/Feature/Analise/SectorCrudTest.php::test_edita_nome_e_situacao. Processo elementar independente: menor unidade com significado para o gestor; completa por si (altera os dados e recebe a confirmação); deixa o negócio consistente (nome continua único); lógica única (alteração do setor existente). Classificação: mantém ALI, EE. TD=4 (nome, situação, mensagem, ação salvar). AR=2 (Setor, Trilha de auditoria). Registros automáticos contados como FTR (premissa P4): Trilha de auditoria. Recontagem 16/10/2026: alterada (linha 179 da contagem de 01/10/2026: "Setores - alterar", EE Baixa 3 PF, TD 4, AR 1). Motivo: AR 1→2: o controller grava a Trilha de auditoria explicitamente (AuditService). PF inalterado (EE Baixa).
A34: =IF(H34="",IF(C34="",A33,A33+1),A33) | B34: =IF(A34=A33,"",CONCATENATE("F",A34)) | C34: Setores - ativar ou inativar | H34: EE | I34: I | J34: 4 | K34: 3 | L34: =CONCATENATE(H34,M34) | M34: =IF(OR(ISBLANK(J34),ISBLANK(K34)),IF(OR(H34="ALI",H34="AIE"),"L",IF(ISBLANK(H34),"","A")),IF(H34="EE",IF(K34>=3,IF(J34>=5,"H","A"),IF(K34>=2,IF(J34>=16,"H",IF(J34<=4,"L","A")),IF(J34<=15,"L","A"))),IF(OR(H34="SE",H34="CE"),IF(K34>=4,IF(J34>=6,"H","A"),IF(K34>=2,IF(J34>=20,"H",IF(J34<=5,"L","A")),IF(J34<=19,"L","A"))),IF(OR(H34="ALI",H34="AIE"),IF(K34>=6,IF(J34>=20,"H","A"),IF(K34>=2,IF(J34>=51,"H",IF(J34<=19,"L","A")),IF(J34<=50,"L","A"))))))) | N34: =IF(M34="L","Baixa",IF(M34="A","Média",IF(M34="","","Alta"))) | O34: =IF(ISBLANK(H34),"",IF(H34="ALI",IF(M34="L",7,IF(M34="A",10,15)),IF(H34="AIE",IF(M34="L",5,IF(M34="A",7,10)),IF(H34="SE",IF(M34="L",4,IF(M34="A",5,7)),IF(OR(H34="EE",H34="CE"),IF(M34="L",3,IF(M34="A",4,6))))))) | P34: =IF(I34="I",O34*Contagem!$W$15,IF(I34="E",O34*Contagem!$W$17,IF(I34="A",O34*Contagem!$W$16,IF(I34="T",O34*Contagem!$W$18,"")))) | Q34: Prova: Rota PUT /gestao/setores/{sector}/ativacao (permissão manter-setores). Tela: gestao/setores/index. O gestor liga ou desliga o setor. Conta processos em análise ou em pendência do setor, grava a situação e a Trilha de auditoria; avisa sem bloquear. Teste: tests/Feature/Analise/SectorCrudTest.php::test_inativar_setor_com_processo_em_aberto_avisa_mas_nao_bloqueia. Processo elementar independente: menor unidade com significado para o gestor; completa por si (alterna e recebe confirmação e aviso); deixa o negócio consistente (setor preservado, sem exclusão); lógica única (inativação com aviso de processos em aberto, distinta da edição). Classificação: mantém ALI, EE. TD=4 (setor, situação, mensagem (inclui o aviso com a quantidade de processos em aberto), ação ativar/inativar). AR=3 (Setor, Solicitação de viabilidade, Trilha de auditoria). Registros automáticos contados como FTR (premissa P4): Trilha de auditoria. Recontagem 16/10/2026: alterada (linha 180 da contagem de 01/10/2026: "Setores - ativar ou inativar", EE Média 4 PF, TD 5, AR 2). Motivo: TD 5→4: o aviso de processos em aberto é parte da mensagem (mensagens = 1 DER). AR 2→3: inclui a Trilha de auditoria gravada pelo controller. PF inalterado (EE Média).
A35: =IF(H35="",IF(C35="",A34,A34+1),A34) | B35: =IF(A35=A34,"",CONCATENATE("F",A35)) | C35: Setores - vincular analistas | H35: EE | I35: I | J35: 4 | K35: 3 | L35: =CONCATENATE(H35,M35) | M35: =IF(OR(ISBLANK(J35),ISBLANK(K35)),IF(OR(H35="ALI",H35="AIE"),"L",IF(ISBLANK(H35),"","A")),IF(H35="EE",IF(K35>=3,IF(J35>=5,"H","A"),IF(K35>=2,IF(J35>=16,"H",IF(J35<=4,"L","A")),IF(J35<=15,"L","A"))),IF(OR(H35="SE",H35="CE"),IF(K35>=4,IF(J35>=6,"H","A"),IF(K35>=2,IF(J35>=20,"H",IF(J35<=5,"L","A")),IF(J35<=19,"L","A"))),IF(OR(H35="ALI",H35="AIE"),IF(K35>=6,IF(J35>=20,"H","A"),IF(K35>=2,IF(J35>=51,"H",IF(J35<=19,"L","A")),IF(J35<=50,"L","A"))))))) | N35: =IF(M35="L","Baixa",IF(M35="A","Média",IF(M35="","","Alta"))) | O35: =IF(ISBLANK(H35),"",IF(H35="ALI",IF(M35="L",7,IF(M35="A",10,15)),IF(H35="AIE",IF(M35="L",5,IF(M35="A",7,10)),IF(H35="SE",IF(M35="L",4,IF(M35="A",5,7)),IF(OR(H35="EE",H35="CE"),IF(M35="L",3,IF(M35="A",4,6))))))) | P35: =IF(I35="I",O35*Contagem!$W$15,IF(I35="E",O35*Contagem!$W$17,IF(I35="A",O35*Contagem!$W$16,IF(I35="T",O35*Contagem!$W$18,"")))) | Q35: Prova: Rota PUT /gestao/setores/{sector}/analistas (permissão manter-setores). Tela: gestao/setores/index. O gestor define o conjunto exato de analistas do setor, escolhidos entre usuários ativos com perfil que concede analisar-processos. Valida os usuários, grava o vínculo N:N em transação e a Trilha de auditoria com antes e depois. Teste: tests/Feature/Analise/SectorCrudTest.php::test_vincula_e_desvincula_analistas_auditado. Processo elementar independente: menor unidade com significado para o gestor; completa por si (marca analistas e recebe a confirmação); deixa o negócio consistente (vínculo sincronizado sem afetar outros setores); lógica única (sincroniza vínculo analista-setor). Classificação: mantém ALI, EE. TD=4 (setor, analistas, mensagem, ação salvar vínculo). AR=3 (Setor, Usuário, Trilha de auditoria). Registros automáticos contados como FTR (premissa P4): Trilha de auditoria. Recontagem 16/10/2026: alterada (linha 181 da contagem de 01/10/2026: "Setores - vincular analistas", EE Baixa 3 PF, TD 4, AR 2). Motivo: AR 2→3: inclui a Trilha de auditoria gravada com antes/depois do vínculo. PF 3→4 (EE Média).
A36: =IF(H36="",IF(C36="",A35,A35+1),A35) | B36: =IF(A36=A35,"",CONCATENATE("F",A36)) | L36: =CONCATENATE(H36,M36) | M36: =IF(OR(ISBLANK(J36),ISBLANK(K36)),IF(OR(H36="ALI",H36="AIE"),"L",IF(ISBLANK(H36),"","A")),IF(H36="EE",IF(K36>=3,IF(J36>=5,"H","A"),IF(K36>=2,IF(J36>=16,"H",IF(J36<=4,"L","A")),IF(J36<=15,"L","A"))),IF(OR(H36="SE",H36="CE"),IF(K36>=4,IF(J36>=6,"H","A"),IF(K36>=2,IF(J36>=20,"H",IF(J36<=5,"L","A")),IF(J36<=19,"L","A"))),IF(OR(H36="ALI",H36="AIE"),IF(K36>=6,IF(J36>=20,"H","A"),IF(K36>=2,IF(J36>=51,"H",IF(J36<=19,"L","A")),IF(J36<=50,"L","A"))))))) | N36: =IF(M36="L","Baixa",IF(M36="A","Média",IF(M36="","","Alta"))) | O36: =IF(ISBLANK(H36),"",IF(H36="ALI",IF(M36="L",7,IF(M36="A",10,15)),IF(H36="AIE",IF(M36="L",5,IF(M36="A",7,10)),IF(H36="SE",IF(M36="L",4,IF(M36="A",5,7)),IF(OR(H36="EE",H36="CE"),IF(M36="L",3,IF(M36="A",4,6))))))) | P36: =IF(I36="I",O36*Contagem!$W$15,IF(I36="E",O36*Contagem!$W$17,IF(I36="A",O36*Contagem!$W$16,IF(I36="T",O36*Contagem!$W$18,""))))
A37: =IF(H37="",IF(C37="",A36,A36+1),A36) | B37: =IF(A37=A36,"",CONCATENATE("F",A37)) | C37: Perfis de acesso | L37: =CONCATENATE(H37,M37) | M37: =IF(OR(ISBLANK(J37),ISBLANK(K37)),IF(OR(H37="ALI",H37="AIE"),"L",IF(ISBLANK(H37),"","A")),IF(H37="EE",IF(K37>=3,IF(J37>=5,"H","A"),IF(K37>=2,IF(J37>=16,"H",IF(J37<=4,"L","A")),IF(J37<=15,"L","A"))),IF(OR(H37="SE",H37="CE"),IF(K37>=4,IF(J37>=6,"H","A"),IF(K37>=2,IF(J37>=20,"H",IF(J37<=5,"L","A")),IF(J37<=19,"L","A"))),IF(OR(H37="ALI",H37="AIE"),IF(K37>=6,IF(J37>=20,"H","A"),IF(K37>=2,IF(J37>=51,"H",IF(J37<=19,"L","A")),IF(J37<=50,"L","A"))))))) | N37: =IF(M37="L","Baixa",IF(M37="A","Média",IF(M37="","","Alta"))) | O37: =IF(ISBLANK(H37),"",IF(H37="ALI",IF(M37="L",7,IF(M37="A",10,15)),IF(H37="AIE",IF(M37="L",5,IF(M37="A",7,10)),IF(H37="SE",IF(M37="L",4,IF(M37="A",5,7)),IF(OR(H37="EE",H37="CE"),IF(M37="L",3,IF(M37="A",4,6))))))) | P37: =IF(I37="I",O37*Contagem!$W$15,IF(I37="E",O37*Contagem!$W$17,IF(I37="A",O37*Contagem!$W$16,IF(I37="T",O37*Contagem!$W$18,""))))
A38: =IF(H38="",IF(C38="",A37,A37+1),A37) | B38: =IF(A38=A37,"",CONCATENATE("F",A38)) | C38: Dados - Perfil de acesso | H38: ALI | I38: I | J38: 3 | K38: 1 | L38: =CONCATENATE(H38,M38) | M38: =IF(OR(ISBLANK(J38),ISBLANK(K38)),IF(OR(H38="ALI",H38="AIE"),"L",IF(ISBLANK(H38),"","A")),IF(H38="EE",IF(K38>=3,IF(J38>=5,"H","A"),IF(K38>=2,IF(J38>=16,"H",IF(J38<=4,"L","A")),IF(J38<=15,"L","A"))),IF(OR(H38="SE",H38="CE"),IF(K38>=4,IF(J38>=6,"H","A"),IF(K38>=2,IF(J38>=20,"H",IF(J38<=5,"L","A")),IF(J38<=19,"L","A"))),IF(OR(H38="ALI",H38="AIE"),IF(K38>=6,IF(J38>=20,"H","A"),IF(K38>=2,IF(J38>=51,"H",IF(J38<=19,"L","A")),IF(J38<=50,"L","A"))))))) | N38: =IF(M38="L","Baixa",IF(M38="A","Média",IF(M38="","","Alta"))) | O38: =IF(ISBLANK(H38),"",IF(H38="ALI",IF(M38="L",7,IF(M38="A",10,15)),IF(H38="AIE",IF(M38="L",5,IF(M38="A",7,10)),IF(H38="SE",IF(M38="L",4,IF(M38="A",5,7)),IF(OR(H38="EE",H38="CE"),IF(M38="L",3,IF(M38="A",4,6))))))) | P38: =IF(I38="I",O38*Contagem!$W$15,IF(I38="E",O38*Contagem!$W$17,IF(I38="A",O38*Contagem!$W$16,IF(I38="T",O38*Contagem!$W$18,"")))) | Q38: Prova: tabelas roles e role_has_permissions (Spatie) da migration database/migrations/2026_06_09_234627_create_permission_tables.php e coluna protegido da migration database/migrations/2026_10_14_090000_add_protegido_to_roles_table.php; regras em app/Support/RoleProtection.php e app/Support/PerfisSolicitaveis.php. Mantido por Perfis de acesso - incluir, alterar e excluir (Gestao\RoleController). Teste: tests/Feature/Roles/ManageRolesTest.php::test_permissoes_de_perfil_novo_tem_efeito_imediato. Arquivo lógico: desde 14/10/2026 (commits 4e7e897f, a61f229c, 0872c807, 23ee97e1) o comportamento da gestão depende só das permissões marcadas no perfil: abas de usuários (acessar-gestao), candidatos a analista do setor (analisar-processos), escalonamento e perfis que o servidor pode solicitar no primeiro acesso AD. O administrador cria, renomeia, ajusta permissões e exclui perfis pela tela; o perfil existe sem usuário vinculado (exclusão só é barrada quando há vínculo), logo passa no teste de independência e não é subgrupo de Usuário. Não é dado de código: o conjunto de permissões muda o que cada conta pode fazer e não se substitui pelo nome. O catálogo de permissões (tabela permissions, descrição e grupo em app/Support/PermissionCatalog.php) é carregado por seeder e não é mantido pelo usuário: dado de código, não conta. role_has_permissions só tem chaves e entra como DER (permissões concedidas). TD=3 (nome do perfil, permissões concedidas, protegido). TR=1 (Perfil de acesso). Recontagem 16/10/2026: nova (não constava da contagem de 01/10/2026).
A39: =IF(H39="",IF(C39="",A38,A38+1),A38) | B39: =IF(A39=A38,"",CONCATENATE("F",A39)) | C39: Perfis de acesso - consultar | H39: SE | I39: I | J39: 8 | K39: 3 | L39: =CONCATENATE(H39,M39) | M39: =IF(OR(ISBLANK(J39),ISBLANK(K39)),IF(OR(H39="ALI",H39="AIE"),"L",IF(ISBLANK(H39),"","A")),IF(H39="EE",IF(K39>=3,IF(J39>=5,"H","A"),IF(K39>=2,IF(J39>=16,"H",IF(J39<=4,"L","A")),IF(J39<=15,"L","A"))),IF(OR(H39="SE",H39="CE"),IF(K39>=4,IF(J39>=6,"H","A"),IF(K39>=2,IF(J39>=20,"H",IF(J39<=5,"L","A")),IF(J39<=19,"L","A"))),IF(OR(H39="ALI",H39="AIE"),IF(K39>=6,IF(J39>=20,"H","A"),IF(K39>=2,IF(J39>=51,"H",IF(J39<=19,"L","A")),IF(J39<=50,"L","A"))))))) | N39: =IF(M39="L","Baixa",IF(M39="A","Média",IF(M39="","","Alta"))) | O39: =IF(ISBLANK(H39),"",IF(H39="ALI",IF(M39="L",7,IF(M39="A",10,15)),IF(H39="AIE",IF(M39="L",5,IF(M39="A",7,10)),IF(H39="SE",IF(M39="L",4,IF(M39="A",5,7)),IF(OR(H39="EE",H39="CE"),IF(M39="L",3,IF(M39="A",4,6))))))) | P39: =IF(I39="I",O39*Contagem!$W$15,IF(I39="E",O39*Contagem!$W$17,IF(I39="A",O39*Contagem!$W$16,IF(I39="T",O39*Contagem!$W$18,"")))) | Q39: Prova: Rota GET /gestao/perfis (permissão manter-perfis). Tela: gestao/perfis/index. O administrador busca perfis por nome. Lê perfis com permissões, conta usuários vinculados (withCount) e marca os protegidos (coluna protegido ou perfil apontado pelo parâmetro portal.perfil_cidadao). Não grava. A exportação (?formato=csv/xlsx/pdf, ReportExporter) não tem botão nesta tela (a página não usa ExportMenu; só é alcançável digitando a URL) e não é contada como função; a consulta da tela não grava Trilha de auditoria (o log só ocorre no ramo ?formato=), por isso continua sem FTR de registro. Teste: tests/Feature/Roles/ManageRolesTest.php::test_administrador_lista_perfis_com_permissoes_e_vinculos e ::test_listagem_marca_protegido_no_campo_structural. Processo elementar independente: menor unidade com significado para o administrador; completa por si (busca até a lista); deixa o negócio consistente (nada muda); lógica única (perfis com contagem de usuários e indicação de protegido). Classificação: exibe quantidade de usuários por perfil, dado derivado: SE, não CE (§5.5.3). TD=8 (busca por nome, nome do perfil, permissões, quantidade de usuários vinculados, protegido, descrição da permissão, grupo da permissão, ação de consultar). AR=3 (Perfil de acesso, Usuário, Parâmetro). Recontagem 16/10/2026: alterada (linha 209 da contagem de 01/10/2026: "Perfis de acesso - consultar", SE Baixa 4 PF, TD 7, AR 1). Motivo: TD 7→8: busca por nome passou a ser server-driven. AR 1→3: o perfil virou ALI próprio (Perfil de acesso); a contagem de usuários lê Usuário e a marca de protegido lê o parâmetro portal.perfil_cidadao (Parâmetro). PF 4→5 (SE Média).
